Workbook

Sheet 1_ThucThe
A1: 1. DANH SÁCH THỰC THỂ / LỚP
A2: Số thuộc tính và số phương thức đếm bằng công thức từ sheet 2 và 3.
A4: STT | B4: Tên lớp | C4: Tên tiếng Việt | D4: Loại | E4: Nhóm nghiệp vụ | F4: Mô tả | G4: Khóa chính | H4: Enum trạng thái | I4: Quy tắc NV liên quan | J4: Use case liên quan | K4: Số thuộc tính | L4: Số phương thức | M4: Nguồn
A5: 1 | B5: ToaNha | C5: Tòa nhà | D5: Thực thể | E5: Tòa nhà + Phòng | F5: Thông tin tòa, cấu hình kỳ thu, tài khoản nhận tiền. Chỉ 1 bản ghi. | G5: maToa | H5: — | J5: UC01.05–UC01.07, UC05.07 | K5: =COUNTIF('2_ThuocTinh'!$B:$B,B5) -> 12 | L5: =COUNTIF('3_PhuongThuc'!$B:$B,B5) -> 3 | M5: ERD v1.5
A6: 2 | B6: Phong | C6: Phòng | D6: Thực thể | E6: Tòa nhà + Phòng | F6: Phòng cho thuê (20–30 phòng). | G6: maPhong | H6: TrangThaiPhong | I6: BR-DM-02, BR-DM-03, BR-DM-04, BR-CT-04 | J6: UC02.01, UC02.05, UC02.06, UC03.02, UC08.06 | K6: =COUNTIF('2_ThuocTinh'!$B:$B,B6) -> 8 | L6: =COUNTIF('3_PhuongThuc'!$B:$B,B6) -> 7 | M6: ERD v1.5
A7: 3 | B7: TaiSan | C7: Tài sản trong phòng | D7: Thực thể | E7: Tòa nhà + Phòng | F7: Danh mục tài sản của phòng kèm tình trạng. | G7: maTaiSan | H7: — | J7: UC02.02 | K7: =COUNTIF('2_ThuocTinh'!$B:$B,B7) -> 6 | L7: =COUNTIF('3_PhuongThuc'!$B:$B,B7) -> 1 | M7: ERD v1.5
A8: 4 | B8: BangGia | C8: Bảng giá | D8: Thực thể | E8: Tòa nhà + Phòng | F8: Đơn giá điện, nước, phí dịch vụ cố định; lưu theo phiên bản hiệu lực. | G8: maKhoan | H8: — | I8: BR-DM-01 | J8: UC02.03, UC02.04, UC05.04 | K8: =COUNTIF('2_ThuocTinh'!$B:$B,B8) -> 8 | L8: =COUNTIF('3_PhuongThuc'!$B:$B,B8) -> 2 | M8: ERD v1.5
A9: 5 | B9: TaiKhoan | C9: Tài khoản | D9: Thực thể | E9: Tài khoản + Thông báo | F9: Tài khoản đăng nhập của chủ nhà và khách (1 tài khoản/phòng). | G9: maTaiKhoan | H9: TrangThaiTK | I9: BR-CT-01 | J9: UC01.01–UC01.04, UC01.08, UC03.07, UC04.09 | K9: =COUNTIF('2_ThuocTinh'!$B:$B,B9) -> 9 | L9: =COUNTIF('3_PhuongThuc'!$B:$B,B9) -> 6 | M9: ERD v1.5
A10: 6 | B10: NhatKyThaoTac | C10: Nhật ký thao tác | D10: Thực thể | E10: Tài khoản + Thông báo | F10: Audit log các thao tác quan trọng. | G10: maNhatKy | H10: — | I10: Mục 11 | J10: UC01.09 | K10: =COUNTIF('2_ThuocTinh'!$B:$B,B10) -> 7 | L10: =COUNTIF('3_PhuongThuc'!$B:$B,B10) -> 2 | M10: ERD v1.5
A11: 7 | B11: ThongBao | C11: Thông báo | D11: Thực thể | E11: Tài khoản + Thông báo | F11: Thông báo trong hệ thống (tự động hoặc chủ nhà gửi). | G11: maThongBao | H11: — | J11: UC08.01, UC08.03 | K11: =COUNTIF('2_ThuocTinh'!$B:$B,B11) -> 8 | L11: =COUNTIF('3_PhuongThuc'!$B:$B,B11) -> 2 | M11: ERD v1.5
A12: 8 | B12: ThongBaoNguoiNhan | C12: Người nhận thông báo | D12: Lớp liên kết | E12: Tài khoản + Thông báo | F12: Liên kết thông báo – tài khoản, trạng thái đã đọc. | G12: maThongBao, maTaiKhoan | H12: — | J12: UC08.02 | K12: =COUNTIF('2_ThuocTinh'!$B:$B,B12) -> 4 | L12: =COUNTIF('3_PhuongThuc'!$B:$B,B12) -> 2 | M12: ERD v1.5
A13: 9 | B13: KhachThue | C13: Khách thuê | D13: Thực thể | E13: Hợp đồng thuê phòng | F13: Hồ sơ người đứng tên hợp đồng; giữ lại để nhận diện khách thuê lại. | G13: maKhach | H13: — | I13: BR-CT-06 | J13: UC03.01, UC03.09 | K13: =COUNTIF('2_ThuocTinh'!$B:$B,B13) -> 8 | L13: =COUNTIF('3_PhuongThuc'!$B:$B,B13) -> 3 | M13: ERD v1.5
A14: 10 | B14: HopDong | C14: Hợp đồng thuê | D14: Thực thể | E14: Hợp đồng thuê phòng | F14: Điều khoản chính của hợp đồng giấy và vòng đời thuê. | G14: maHopDong | H14: TrangThaiHD | I14: BR-CT-02, BR-CT-03, BR-CT-05, BR-HD-03, BR-TL-01 | J14: UC03.02–UC03.08, UC04.02–UC04.04, UC04.09, UC05.04 | K14: =COUNTIF('2_ThuocTinh'!$B:$B,B14) -> 19 | L14: =COUNTIF('3_PhuongThuc'!$B:$B,B14) -> 14 | M14: ERD v1.5
A15: 11 | B15: NguoiO | C15: Người ở cùng | D15: Thực thể | E15: Hợp đồng thuê phòng | F15: Người ở cùng khai báo trong hồ sơ phòng (không có tài khoản). | G15: maNguoiO | H15: — | I15: BR-CT-04 | J15: UC03.02 | K15: =COUNTIF('2_ThuocTinh'!$B:$B,B15) -> 7 | L15: =COUNTIF('3_PhuongThuc'!$B:$B,B15) -> 2 | M15: ERD v1.5
A16: 12 | B16: HopDongDichVu | C16: Dịch vụ áp dụng theo HĐ | D16: Lớp liên kết | E16: Hợp đồng thuê phòng | F16: Phí dịch vụ cố định HĐ đăng ký (internet, vệ sinh, gửi xe…). | G16: maHopDong, maKhoan | H16: — | J16: UC03.03, UC05.04 | K16: =COUNTIF('2_ThuocTinh'!$B:$B,B16) -> 5 | L16: =COUNTIF('3_PhuongThuc'!$B:$B,B16) -> 1 | M16: ERD v1.5
A17: 13 | B17: BanGiaoTaiSan | C17: Bàn giao tài sản | D17: Thực thể | E17: Hợp đồng thuê phòng | F17: Tình trạng tài sản khi nhận phòng / trả phòng. | G17: maBanGiao | H17: — | I17: BR-TL-02 | J17: UC03.06, UC04.04, UC04.05 | K17: =COUNTIF('2_ThuocTinh'!$B:$B,B17) -> 8 | L17: =COUNTIF('3_PhuongThuc'!$B:$B,B17) -> 3 | M17: ERD v1.5
A18: 14 | B18: LichSuHopDong | C18: Lịch sử thay đổi HĐ | D18: Thực thể | E18: Hợp đồng thuê phòng | F18: Gia hạn, điều chỉnh giá/phí, thêm bớt người ở (giá trị cũ/mới). | G18: maLichSu | H18: — | J18: UC04.02 | K18: =COUNTIF('2_ThuocTinh'!$B:$B,B18) -> 9 | L18: =COUNTIF('3_PhuongThuc'!$B:$B,B18) -> 1 | M18: ERD v1.5
A19: 15 | B19: ChiSo | C19: Chỉ số điện nước | D19: Thực thể | E19: Thông báo tiền | F19: Chỉ số công tơ theo kỳ, theo HĐ. | G19: maChiSo | H19: — | I19: BR-HD-02 | J19: UC03.06, UC04.04, UC05.01–UC05.04 | K19: =COUNTIF('2_ThuocTinh'!$B:$B,B19) -> 9 | L19: =COUNTIF('3_PhuongThuc'!$B:$B,B19) -> 3 | M19: ERD v1.5
A20: 16 | B20: ThongBaoTien | C20: Thông báo tiền | D20: Thực thể | E20: Thông báo tiền | F20: Thông báo tiền hằng tháng / khi ký HĐ / thu thêm quyết toán. | G20: maThongBaoTien | H20: TrangThaiTBT | I20: BR-HD-01–BR-HD-06, BR-TT-03 | J20: UC05.04–UC05.09, UC06.02, UC06.04–UC06.06, UC06.08, UC07.07 | K20: =COUNTIF('2_ThuocTinh'!$B:$B,B20) -> 12 | L20: =COUNTIF('3_PhuongThuc'!$B:$B,B20) -> 8 | M20: ERD v1.5
A21: 17 | B21: DongThongBaoTien | C21: Dòng thông báo tiền | D21: Thực thể | E21: Thông báo tiền | F21: Chi tiết từng khoản trong thông báo tiền. | G21: maDong | H21: — | I21: BR-HD-05 | J21: UC05.04, UC05.05 | K21: =COUNTIF('2_ThuocTinh'!$B:$B,B21) -> 13 | L21: =COUNTIF('3_PhuongThuc'!$B:$B,B21) -> 1 | M21: ERD v1.5
A22: 18 | B22: BaoThanhToan | C22: Báo đã chuyển khoản | D22: Thực thể | E22: Thanh toán | F22: Khách báo đã chuyển khoản, chờ chủ nhà xác nhận. | G22: maBaoTT | H22: TrangThaiBaoTT | J22: UC06.01–UC06.03, UC06.05 | K22: =COUNTIF('2_ThuocTinh'!$B:$B,B22) -> 6 | L22: =COUNTIF('3_PhuongThuc'!$B:$B,B22) -> 3 | M22: ERD v1.5
A23: 19 | B23: PhieuThu | C23: Phiếu thu | D23: Thực thể | E23: Thanh toán | F23: Chứng từ thu nội bộ (không phải hóa đơn điện tử). | G23: soPhieuThu | H23: TrangThaiPT | I23: BR-TT-02, BR-HD-06 | J23: UC06.04–UC06.07 | K23: =COUNTIF('2_ThuocTinh'!$B:$B,B23) -> 9 | L23: =COUNTIF('3_PhuongThuc'!$B:$B,B23) -> 4 | M23: ERD v1.5
A24: 20 | B24: QuyetToan | C24: Quyết toán cọc | D24: Thực thể | E24: Trả phòng | F24: Bảng quyết toán khi trả phòng. | G24: maQuyetToan | H24: TrangThaiQT | I24: BR-TL-01, BR-TL-03, BR-TT-04 | J24: UC04.05–UC04.11 | K24: =COUNTIF('2_ThuocTinh'!$B:$B,B24) -> 12 | L24: =COUNTIF('3_PhuongThuc'!$B:$B,B24) -> 9 | M24: ERD v1.5
A25: 21 | B25: DongQuyetToan | C25: Dòng quyết toán | D25: Thực thể | E25: Trả phòng | F25: Từng khoản hoàn / trừ trong quyết toán. | G25: maDong | H25: — | I25: BR-TL-02 | J25: UC04.05 | K25: =COUNTIF('2_ThuocTinh'!$B:$B,B25) -> 6 | L25: =COUNTIF('3_PhuongThuc'!$B:$B,B25) -> 1 | M25: ERD v1.5
A26: 22 | B26: PhieuChi | C26: Phiếu chi | D26: Thực thể | E26: Trả phòng | F26: Phiếu chi hoàn cọc. | G26: soPhieuChi | H26: — | J26: UC04.07 | K26: =COUNTIF('2_ThuocTinh'!$B:$B,B26) -> 6 | L26: =COUNTIF('3_PhuongThuc'!$B:$B,B26) -> 1 | M26: ERD v1.5
A27: 23 | B27: SuCo | C27: Sự cố | D27: Thực thể | E27: Sự cố | F27: Sự cố khách báo và quá trình xử lý. | G27: maSuCo | H27: TrangThaiSuCo | I27: BR-SC-01, BR-SC-02, BR-SC-03 | J27: UC05.05, UC07.01–UC07.07 | K27: =COUNTIF('2_ThuocTinh'!$B:$B,B27) -> 12 | L27: =COUNTIF('3_PhuongThuc'!$B:$B,B27) -> 6 | M27: ERD v1.5
A28: 24 | B28: LichSuSuCo | C28: Lịch sử xử lý sự cố | D28: Thực thể | E28: Sự cố | F28: Lịch sử đổi trạng thái sự cố. | G28: maLichSu | H28: — | J28: UC07.02 | K28: =COUNTIF('2_ThuocTinh'!$B:$B,B28) -> 7 | L28: =COUNTIF('3_PhuongThuc'!$B:$B,B28) -> 1 | M28: ERD v1.5
A29: 25 | B29: DichVuThongBaoTien | C29: Dịch vụ lập thông báo tiền | D29: Lớp dịch vụ (không lưu CSDL) | E29: Thông báo tiền | F29: Điều phối lập / phát hành thông báo hàng loạt. | G29: — | H29: — | I29: BR-HD-01, BR-HD-02 | J29: UC05.04, UC05.06 | K29: =COUNTIF('2_ThuocTinh'!$B:$B,B29) -> 0 | L29: =COUNTIF('3_PhuongThuc'!$B:$B,B29) -> 3 | M29: Đề xuất bổ sung
A30: 26 | B30: BoHenGio | C30: Bộ hẹn giờ hệ thống | D30: Lớp dịch vụ (không lưu CSDL) | E30: Tác nhân tự động | F30: Job chạy hằng ngày: nhắc chỉ số, nhắc hạn, quá hạn, HĐ sắp hết hạn. | G30: — | H30: — | J30: UC04.01, UC05.01, UC06.08 | K30: =COUNTIF('2_ThuocTinh'!$B:$B,B30) -> 0 | L30: =COUNTIF('3_PhuongThuc'!$B:$B,B30) -> 1 | M30: Đề xuất bổ sung
A31: 27 | B31: DichVuViecCanLam | C31: Danh sách việc cần làm | D31: Lớp dịch vụ (không lưu CSDL) | E31: Thông báo & báo cáo | F31: Màn hình chính của chủ nhà. | G31: — | H31: — | J31: UC08.04 | K31: =COUNTIF('2_ThuocTinh'!$B:$B,B31) -> 0 | L31: =COUNTIF('3_PhuongThuc'!$B:$B,B31) -> 1 | M31: Đề xuất bổ sung
A32: 28 | B32: DichVuBaoCao | C32: Báo cáo vận hành | D32: Lớp dịch vụ (không lưu CSDL) | E32: Thông báo & báo cáo | F32: Các chỉ số báo cáo cho chủ nhà. | G32: — | H32: — | J32: UC08.05–UC08.09 | K32: =COUNTIF('2_ThuocTinh'!$B:$B,B32) -> 0 | L32: =COUNTIF('3_PhuongThuc'!$B:$B,B32) -> 8 | M32: Đề xuất bổ sung
A33: 29 | B33: DichVuKhoiTao | C33: Khởi tạo dữ liệu | D33: Lớp dịch vụ (không lưu CSDL) | E33: Cài đặt (P00) | F33: Nhập dữ liệu ban đầu của tòa đang vận hành. | G33: — | H33: — | J33: UC01.03, UC01.08 | K33: =COUNTIF('2_ThuocTinh'!$B:$B,B33) -> 0 | L33: =COUNTIF('3_PhuongThuc'!$B:$B,B33) -> 1 | M33: Đề xuất bổ sung
J34: Tổng | K34: =SUM(K5:K33) -> 210 | L34: =SUM(L5:L33) -> 100

Sheet 2_ThuocTinh
A1: 2. THUỘC TÍNH CỦA TỪNG THỰC THỂ
A2: Bắt buộc: Y / N / Có điều kiện. Dòng nền vàng = đề xuất bổ sung ngoài ERD v1.6.
A4: STT | B4: Lớp | C4: Tên thuộc tính | D4: Tên hiển thị | E4: Kiểu (ERD) | F4: Kiểu CSDL gợi ý | G4: Định dạng / Mẫu | H4: Miền giá trị (Data range) | I4: Bắt buộc | J4: Khóa | K4: Tham chiếu (FK →) | L4: Mặc định | M4: Mô tả & ràng buộc | N4: Nguồn
A5: 1 | B5: ToaNha | C5: maToa | D5: Mã tòa | E5: String | F5: VARCHAR(10) | G5: Cố định 'TOA01' | H5: Chỉ 1 bản ghi trong toàn hệ thống | I5: Y | J5: PK | L5: TOA01 | M5: Hệ thống cài cho đúng 1 tòa; tạo khi cài đặt, không cho tạo thêm | N5: ERD v1.5
A6: 2 | B6: ToaNha | C6: tenToa | D6: Tên tòa | E6: String | F6: VARCHAR(100) | G6: Văn bản tự do | H6: 1–100 ký tự | I6: Y | M6: In trên thông báo tiền, phiếu thu | N6: ERD v1.5
A7: 3 | B7: ToaNha | C7: diaChi | D7: Địa chỉ tòa | E7: String | F7: VARCHAR(255) | G7: Văn bản tự do | H7: 1–255 ký tự | I7: Y | M7: In trên phiếu thu | N7: ERD v1.5
A8: 4 | B8: ToaNha | C8: noiQuy | D8: Nội quy | E8: String | F8: TEXT | G8: Văn bản nhiều dòng | H8: ≤ 5.000 ký tự | I8: N | M8: Khách xem ở UC01.07 | N8: ERD v1.5
A9: 5 | B9: ToaNha | C9: ngayChotChiSo | D9: Ngày chốt chỉ số | E9: int | F9: TINYINT | G9: Số nguyên | H9: 1–31; nếu lớn hơn số ngày của tháng → lấy ngày cuối tháng | I9: Y | L9: 31 | M9: Mặc định ngày cuối tháng (P00). Bộ hẹn giờ nhắc ghi chỉ số vào ngày này | N9: ERD v1.5
A10: 6 | B10: ToaNha | C10: hanThanhToan | D10: Ngày hạn thanh toán | E10: int | F10: TINYINT | G10: Số nguyên (ngày của tháng sau) | H10: 1–28 | I10: Y | L10: 5 | M10: Hạn thanh toán = ngày này của tháng T+1 (mặc định ngày 5) | N10: ERD v1.5
A11: 7 | B11: ToaNha | C11: nganHang | D11: Ngân hàng nhận tiền | E11: String | F11: VARCHAR(10) | G11: Mã BIN NAPAS 6 chữ số (vd 970436) | H11: ^\d{6}$ | I11: Y | M11: Cần mã BIN để sinh VietQR; giao diện cho chọn theo tên ngân hàng, lưu mã BIN | N11: ERD v1.5
A12: 8 | B12: ToaNha | C12: soTaiKhoan | D12: Số tài khoản | E12: String | F12: VARCHAR(20) | G12: Chỉ chữ số | H12: ^\d{6,19}$ | I12: Y | M12: Tài khoản của chủ nhà; hệ thống không thu hộ (BR-TT-01) | N12: ERD v1.5
A13: 9 | B13: ToaNha | C13: chuTaiKhoan | D13: Chủ tài khoản | E13: String | F13: VARCHAR(100) | G13: CHỮ IN HOA KHÔNG DẤU | H13: 1–100 ký tự | I13: Y | M13: Hiển thị trên VietQR | N13: ERD v1.5
A14: 10 | B14: ToaNha | C14: tenChuNha | D14: Tên chủ nhà | E14: String | F14: VARCHAR(100) | G14: Văn bản tự do | H14: 1–100 ký tự | I14: Y | M14: In trên phiếu thu | N14: ERD v1.5
A15: 11 | B15: ToaNha | C15: sdtChuNha | D15: SĐT chủ nhà | E15: String | F15: VARCHAR(10) | G15: SĐT di động VN | H15: ^0\d{9}$ | I15: Y | M15: In trên phiếu thu | N15: ERD v1.5
A16: 12 | B16: ToaNha | C16: diaChiChuNha | D16: Địa chỉ chủ nhà (in phiếu thu) | E16: String | F16: VARCHAR(255) | G16: Văn bản tự do | H16: ≤ 255 ký tự | I16: N | L16: = diaChi | M16: In trên phiếu thu (P00 bước 3) | N16: ERD v1.5
A17: 13 | B17: Phong | C17: maPhong | D17: Mã phòng | E17: String | F17: VARCHAR(10) | G17: Chủ nhà nhập, vd P101 | H17: ^[A-Z0-9]{2,10}$; duy nhất | I17: Y | J17: PK | M17: Dùng trong mã thông báo tiền nên chỉ chữ in hoa + số | N17: ERD v1.5
A18: 14 | B18: Phong | C18: maToa | D18: Mã tòa | E18: String | F18: VARCHAR(10) | H18: = TOA01 | I18: Y | J18: FK | K18: ToaNha.maToa | L18: TOA01 | N18: ERD v1.5
A19: 15 | B19: Phong | C19: tang | D19: Tầng | E19: int | F19: TINYINT | G19: Số nguyên | H19: 0–20 (0 = tầng trệt) | I19: Y | M19: Dùng để nhóm danh sách ghi chỉ số và sơ đồ tòa | N19: ERD v1.5
A20: 16 | B20: Phong | C20: dienTich | D20: Diện tích (m²) | E20: float | F20: DECIMAL(6,2) | G20: Số thập phân 2 chữ số | H20: > 0 và ≤ 200 | I20: Y | N20: ERD v1.5
A21: 17 | B21: Phong | C21: soNguoiToiDa | D21: Số người tối đa | E21: int | F21: TINYINT | G21: Số nguyên | H21: 1–10 | I21: Y | M21: BR-CT-04 | N21: ERD v1.5
A22: 18 | B22: Phong | C22: giaNiemYet | D22: Giá niêm yết (VNĐ/tháng) | E22: decimal | F22: DECIMAL(15,0) | G22: #,##0 đ | H22: > 0 và ≤ 100.000.000 | I22: Y | M22: BR-DM-02: đổi giá niêm yết không ảnh hưởng HĐ đang hiệu lực | N22: ERD v1.5
A23: 19 | B23: Phong | C23: coCongToNuoc | D23: Có công tơ nước riêng | E23: boolean | F23: BOOLEAN | G23: true/false | I23: Y | L23: true | M23: false → tiền nước tính theo người/tháng (BangGia.loaiKhoan = NUOC_THEO_NGUOI) | N23: ERD v1.5
A24: 20 | B24: Phong | C24: trangThai | D24: Trạng thái phòng | E24: TrangThaiPhong | F24: VARCHAR(20) | G24: Enum | H24: TRONG | DANG_THUE | NGUNG_KHAI_THAC | I24: Y | L24: TRONG | M24: BR-DM-04. Nhãn 'Sắp trả' KHÔNG phải trạng thái – suy ra từ HĐ hiệu lực có ngayBaoTra | N24: ERD v1.5
A25: 21 | B25: TaiSan | C25: maTaiSan | D25: Mã tài sản | E25: String | F25: VARCHAR(20) | G25: TS + số | H25: Hệ thống sinh | I25: Y | J25: PK | L25: Tự sinh | N25: ERD v1.5
A26: 22 | B26: TaiSan | C26: maPhong | D26: Mã phòng | E26: String | F26: VARCHAR(10) | H26: Tồn tại trong Phong | I26: Y | J26: FK | K26: Phong.maPhong | N26: ERD v1.5
A27: 23 | B27: TaiSan | C27: tenTaiSan | D27: Tên tài sản | E27: String | F27: VARCHAR(100) | G27: vd Điều hòa, Tủ lạnh, Giường | H27: 1–100 ký tự | I27: Y | N27: ERD v1.5
A28: 24 | B28: TaiSan | C28: soLuong | D28: Số lượng | E28: int | F28: SMALLINT | G28: Số nguyên | H28: ≥ 1 | I28: Y | L28: 1 | N28: ERD v1.5
A29: 25 | B29: TaiSan | C29: tinhTrang | D29: Tình trạng hiện tại | E29: String | F29: VARCHAR(255) | G29: Văn bản ngắn | H29: 1–255 ký tự | I29: Y | L29: Tốt | M29: Cập nhật lại sau mỗi lần bàn giao | N29: ERD v1.5
A30: 26 | B30: TaiSan | C30: ghiChu | D30: Ghi chú | E30: String | F30: VARCHAR(500) | H30: ≤ 500 ký tự | I30: N | N30: ERD v1.5
A31: 27 | B31: BangGia | C31: maKhoan | D31: Mã khoản giá | E31: String | F31: VARCHAR(20) | G31: BG + số | H31: Hệ thống sinh; mỗi lần đổi giá tạo bản ghi mới | I31: Y | J31: PK | L31: Tự sinh | M31: Lưu theo phiên bản hiệu lực để tra giá tại một ngày (BR-DM-01) | N31: ERD v1.5
A32: 28 | B32: BangGia | C32: maToa | D32: Mã tòa | E32: String | F32: VARCHAR(10) | H32: = TOA01 | I32: Y | J32: FK | K32: ToaNha.maToa | L32: TOA01 | N32: ERD v1.5
A33: 29 | B33: BangGia | C33: tenKhoan | D33: Tên khoản | E33: String | F33: VARCHAR(100) | G33: vd Điện, Nước, Internet, Vệ sinh, Gửi xe máy | H33: 1–100 ký tự | I33: Y | N33: ERD v1.5
A34: 30 | B34: BangGia | C34: loaiKhoan | D34: Loại khoản | E34: LoaiKhoan | F34: VARCHAR(30) | G34: Enum | H34: DIEN | NUOC | NUOC_THEO_NGUOI | DICH_VU_THEO_PHONG | DICH_VU_THEO_XE | I34: Y | M34: Xem sheet 4_DanhMuc_Enum | N34: ERD v1.5
A35: 31 | B35: BangGia | C35: donGia | D35: Đơn giá (VNĐ) | E35: decimal | F35: DECIMAL(15,0) | G35: #,##0 đ | H35: ≥ 0 | I35: Y | M35: Điện/nước không bậc thang | N35: ERD v1.5
A36: 32 | B36: BangGia | C36: donViTinh | D36: Đơn vị tính | E36: String | F36: VARCHAR(20) | H36: kWh | m3 | người/tháng | phòng/tháng | xe/tháng | I36: Y | M36: Khớp với loaiKhoan | N36: ERD v1.5
A37: 33 | B37: BangGia | C37: ngayApDung | D37: Ngày áp dụng | E37: Date | F37: DATE | G37: yyyy-MM-dd | I37: Y | N37: ERD v1.5
A38: 34 | B38: BangGia | C38: ngayHetHieuLuc | D38: Ngày hết hiệu lực | E38: Date | F38: DATE | G38: yyyy-MM-dd | H38: NULL hoặc ≥ ngayApDung (tính cả ngày này) | I38: N | L38: NULL | M38: NULL = đang áp dụng. Không chồng lấn hiệu lực giữa các bản ghi cùng tenKhoan | N38: ERD v1.5
A39: 35 | B39: TaiKhoan | C39: maTaiKhoan | D39: Mã tài khoản | E39: String | F39: VARCHAR(20) | G39: TK + 4 số, vd TK0001 | H39: Hệ thống sinh, duy nhất | I39: Y | J39: PK | L39: Tự sinh | N39: ERD v1.5
A40: 36 | B40: TaiKhoan | C40: tenDangNhap | D40: Tên đăng nhập (SĐT) | E40: String | F40: VARCHAR(10) | G40: SĐT di động VN | H40: ^0\d{9}$; duy nhất toàn hệ thống | I40: Y | J40: UK | M40: BR-CT-01: SĐT là tên đăng nhập, duy nhất. Khách thuê lại dùng lại tài khoản cũ (mở khóa) | N40: ERD v1.5
A41: 37 | B41: TaiKhoan | C41: matKhauHash | D41: Mật khẩu (băm) | E41: String | F41: VARCHAR(255) | G41: Chuỗi băm bcrypt/argon2 | H41: Mật khẩu gốc ≥ 8 ký tự (giả định) | I41: Y | M41: Không bao giờ lưu/hiển thị mật khẩu gốc (mục 11) | N41: ERD v1.5
...

Sheet 3_PhuongThuc
A1: 3. PHƯƠNG THỨC CỦA TỪNG THỰC THỂ
A2: Chỉ liệt kê phương thức nghiệp vụ; CRUD cơ bản ngầm hiểu theo 8_PhanQuyen. Dòng nền vàng = đề xuất bổ sung.
A4: STT | B4: Lớp | C4: Tên phương thức | D4: Tham số | E4: Kiểu trả về | F4: Mô tả | G4: Tiền điều kiện / Kiểm tra | H4: Kết quả / Hậu điều kiện | I4: Quy tắc NV | J4: Use case | K4: Tác nhân | L4: Nguồn
A5: 1 | B5: ToaNha | C5: capNhatThongTin | D5: tenToa, diaChi, noiQuy, ngayChotChiSo, hanThanhToan | E5: void | F5: Cập nhật thông tin chung của tòa. | G5: ngayChotChiSo 1–31; hanThanhToan 1–28; tên, địa chỉ không rỗng. | H5: Lưu thông tin; ngày chốt/hạn mới áp dụng từ kỳ lập thông báo kế tiếp, không tính lại thông báo đã phát hành. | J5: UC01.05 | K5: Chủ nhà | L5: ERD v1.5
A6: 2 | B6: ToaNha | C6: capNhatTaiKhoanNhanTien | D6: nganHang, soTaiKhoan, chuTaiKhoan, tenChuNha, sdtChuNha, diaChiChuNha | E6: void | F6: Khai báo tài khoản nhận tiền và thông tin in trên phiếu thu (tên, địa chỉ, SĐT chủ nhà); tên và SĐT chủ nhà cũng hiện ở Trang chủ của khách (KT-01.01). | G6: nganHang là mã BIN 6 số; soTaiKhoan chỉ chữ số; sdtChuNha ^0\d{9}$. | H6: Lưu; ghi NhatKyThaoTac. Mã VietQR của các thông báo chưa thu sinh theo tài khoản mới. | I6: BR-TT-01 | J6: UC01.06 | K6: Chủ nhà | L6: ERD v1.5 · sửa ver1.4
A7: 3 | B7: ToaNha | C7: taoMaVietQR | D7: soTien: decimal, noiDung: String | E7: String | F7: Sinh mã VietQR (chuẩn NAPAS/EMVCo) với số tài khoản chủ nhà, số tiền và nội dung chuyển khoản. | G7: soTien > 0; noiDung chỉ chữ + số, ≤ 25 ký tự. | H7: Trả về payload QR (hoặc URL ảnh QR). Cách làm: tự sinh payload EMVCo + CRC16, hoặc dùng dịch vụ ảnh VietQR công khai (img.vietqr.io). | J7: UC05.07 | K7: Hệ thống | L7: ERD v1.5
A8: 4 | B8: Phong | C8: capNhatGiaNiemYet | D8: gia: decimal | E8: void | F8: Đổi giá niêm yết của phòng. | G8: gia > 0. | H8: Lưu giá mới; KHÔNG đổi HopDong.giaThue của HĐ đang hiệu lực. | I8: BR-DM-02 | J8: UC02.01 | K8: Chủ nhà | L8: ERD v1.5
A9: 5 | B9: Phong | C9: chuyenTrangThai | D9: trangThai: TrangThaiPhong | E9: void | F9: Chuyển trạng thái phòng. | G9: Chủ nhà chỉ được TRONG ↔ NGUNG_KHAI_THAC; TRONG ↔ DANG_THUE chỉ do hệ thống (nhận phòng/thanh lý). Không chuyển NGUNG_KHAI_THAC khi phòng có HĐ chưa thanh lý. | H9: Cập nhật trangThai. | I9: BR-DM-04 | J9: UC02.01 | K9: Chủ nhà, Hệ thống | L9: ERD v1.5
A10: 6 | B10: Phong | C10: layHopDongHieuLuc | E10: HopDong | null | F10: Lấy HĐ hiện hành của phòng. | H10: HĐ có trangThai HIEU_LUC (hoặc CHO_NHAN_PHONG); tối đa 1. | I10: BR-CT-03 | K10: Hệ thống | L10: ERD v1.5
A11: 7 | B11: Phong | C11: kiemTraSoNguoi | D11: soNguoi: int | E11: boolean | F11: Kiểm tra tổng số người ở. | G11: soNguoi = 1 (người đứng tên) + số NguoiO đang ở. | H11: true nếu soNguoi ≤ soNguoiToiDa. | I11: BR-CT-04 | J11: UC03.02 | K11: Hệ thống | L11: ERD v1.5
A12: 8 | B12: Phong | C12: coTheXoa | E12: boolean | F12: Kiểm tra được phép xóa phòng. | H12: true chỉ khi phòng chưa từng có HĐ; ngược lại chỉ cho chuyển NGUNG_KHAI_THAC. | I12: BR-DM-03 | J12: UC02.01 | K12: Hệ thống | L12: ERD v1.5
A13: 9 | B13: Phong | C13: xoa | E13: void | F13: Xóa phòng chưa từng có hợp đồng (CN-02.01). | G13: Chỉ CHU_NHA; coTheXoa() = true. | H13: Xóa Phong và TaiSan của phòng; ghi NhatKyThaoTac (HUY, doiTuong = Phong). | I13: BR-DM-03 | J13: UC02.01 | K13: Chủ nhà | L13: Bổ sung ver1.4 (Sidebar v1.3)
A14: 10 | B14: Phong | C14: laSapTra | E14: boolean | F14: Xác định nhãn 'Sắp trả' trên sơ đồ tòa. | H14: true khi HĐ hiệu lực có ngayBaoTra ≠ null và ngayTraThucTe = null; hiển thị kèm ngayTraDuKien. | J14: UC02.05, UC08.06 | K14: Hệ thống | L14: ERD v1.5
A15: 11 | B15: TaiSan | C15: capNhatTinhTrang | D15: tinhTrang: String | E15: void | F15: Cập nhật tình trạng hiện tại của tài sản. | G15: tinhTrang không rỗng. | H15: Lưu; thường gọi sau bàn giao nhận/trả phòng. | J15: UC02.02 | K15: Chủ nhà | L15: ERD v1.5
A16: 12 | B16: BangGia | C16: layDonGiaTai | D16: loaiKhoan, ngay: Date | E16: decimal | F16: Tra đơn giá hiệu lực tại một ngày. | H16: Bản ghi có ngayApDung ≤ ngay và (ngayHetHieuLuc null hoặc ≥ ngay). Khi lập thông báo, ngay = ngày lập thông báo (giá mới áp cho thông báo lập sau thời điểm đổi). | I16: BR-DM-01 | J16: UC05.04 | K16: Hệ thống | L16: ERD v1.5
A17: 13 | B17: BangGia | C17: doiDonGia | D17: giaMoi: decimal, ngayApDung: Date | E17: BangGia | F17: Đổi đơn giá điện, nước hoặc phí dịch vụ. | G17: giaMoi ≥ 0; ngayApDung > ngayApDung của bản ghi hiện hành. | H17: Đóng bản ghi cũ (ngayHetHieuLuc = ngayApDung − 1 ngày), tạo bản ghi mới; thông báo đã phát hành không tính lại; ghi NhatKyThaoTac. | I17: BR-DM-01 | J17: UC02.03, UC02.04 | K17: Chủ nhà | L17: ERD v1.5
A18: 14 | B18: TaiKhoan | C18: taoTaiKhoanKhach | D18: hopDong: HopDong, nguoiO?: NguoiO | E18: TaiKhoan, String (mật khẩu tạm) | F18: Phương thức tạo (static/factory): tạo tài khoản cho người được cấp của HĐ – người đứng tên (mặc định) hoặc một người ở cùng (vd sinh viên khi phụ huynh đứng tên). | G18: HĐ CHO_NHAN_PHONG (gọi từ xacNhanNhanPhong) hoặc HĐ HIEU_LUC chưa có maTaiKhoan (CN-09.03, CN-09.04); nguoiO (nếu có) thuộc HĐ và có soDienThoai hợp lệ. SĐT đã có tài khoản (khách thuê lại) → mở khóa + đặt lại mật khẩu thay vì tạo mới. | H18: tenDangNhap = SĐT người được cấp; vaiTro = KHACH_THUE, phaiDoiMatKhau = true; gán HopDong.maTaiKhoan và HopDong.maNguoiOCapTK (NULL nếu cấp cho người đứng tên); ghi NhatKyThaoTac (TAO); trả mật khẩu tạm hiển thị 1 lần cho chủ nhà. | I18: BR-CT-01 | J18: UC01.03, UC03.07, UC01.08 | K18: Chủ nhà, Hệ thống | L18: ERD v1.5 · sửa ver1.4
A19: 15 | B19: TaiKhoan | C19: dangNhap | D19: sdt: String, matKhau: String | E19: boolean | F19: Xác thực đăng nhập bằng SĐT + mật khẩu. | G19: Từ chối nếu trangThai = DA_KHOA, hoặc KHOA_TAM và chưa hết khoaDenLuc. | H19: Sai → soLanSai + 1; đủ 5 → KHOA_TAM. Đúng → soLanSai = 0; nếu phaiDoiMatKhau = true → chuyển màn hình đổi mật khẩu. | I19: Mục 11 | J19: UC01.01 | K19: Chủ nhà, Khách thuê | L19: ERD v1.5
A20: 16 | B20: TaiKhoan | C20: doiMatKhau | D20: cu: String, moi: String | E20: void | F20: Người dùng tự đổi mật khẩu. | G20: cu khớp hash; moi ≥ 8 ký tự và khác cu. | H20: Lưu hash mới; phaiDoiMatKhau = false. | J20: UC01.02 | K20: Chủ nhà, Khách thuê | L20: ERD v1.5
A21: 17 | B21: TaiKhoan | C21: datLaiMatKhau | E21: String | F21: Chủ nhà đặt lại mật khẩu cho khách. | G21: Chỉ CHU_NHA gọi, áp dụng cho tài khoản KHACH_THUE. Chủ nhà quên mật khẩu → người cài đặt dùng script, không qua giao diện. | H21: Sinh mật khẩu tạm 8 ký tự; phaiDoiMatKhau = true; soLanSai = 0; KHOA_TAM → HOAT_DONG. Trả mật khẩu tạm. | I21: Mục 11 | J21: UC01.04 | K21: Chủ nhà | L21: ERD v1.5
A22: 18 | B22: TaiKhoan | C22: khoa | E22: void | F22: Khóa tài khoản khách. | G22: Không khóa tài khoản CHU_NHA. | H22: trangThai = DA_KHOA. Gọi tự động khi thanh lý HĐ (P05 bước 5). | J22: UC01.03, UC04.09 | K22: Chủ nhà, Hệ thống | L22: ERD v1.5
A23: 19 | B23: TaiKhoan | C23: moKhoa | E23: void | F23: Mở khóa tài khoản. | G23: trangThai ≠ HOAT_DONG. | H23: trangThai = HOAT_DONG; soLanSai = 0. | J23: UC01.03 | K23: Chủ nhà | L23: ERD v1.5
A24: 20 | B24: NhatKyThaoTac | C24: ghiNhan | D24: taiKhoan, doiTuong, hanhDong, noiDung | E24: void | F24: Ghi nhật ký thao tác (chỉ thêm, không sửa/xóa). | G24: Bắt buộc gọi khi tạo/sửa/hủy HopDong, ThongBaoTien, PhieuThu, ChiSo và mỗi lần xuất danh sách tạm trú. | H24: Thêm 1 bản ghi NhatKyThaoTac. | I24: Mục 11 | K24: Hệ thống | L24: ERD v1.5
A25: 21 | B25: NhatKyThaoTac | C25: traCuu | D25: tuNgay: Date, denNgay: Date, doiTuong?: String, maTaiKhoan?: String | E25: List<NhatKyThaoTac> | F25: Tra cứu nhật ký theo khoảng ngày; lọc thêm theo đối tượng và người thực hiện (tùy chọn). | G25: Chỉ CHU_NHA; tuNgay ≤ denNgay. | H25: Danh sách sắp xếp thời điểm giảm dần. Chỉ đọc: không có phương thức sửa / xóa nhật ký. | J25: UC01.09 | K25: Chủ nhà | L25: ERD v1.5
A26: 22 | B26: ThongBao | C26: guiDen | D26: dsTaiKhoan: List<TaiKhoan> | E26: void | F26: Gửi thông báo đến danh sách tài khoản. | G26: dsTaiKhoan không rỗng. | H26: Tạo ThongBaoNguoiNhan (daDoc = false) cho từng tài khoản. | J26: UC08.03 | K26: Hệ thống | L26: ERD v1.5
A27: 23 | B27: ThongBao | C27: guiToanBoKhach | E27: void | F27: Gửi thông báo chung cho cả tòa (cắt điện, bảo trì, nội quy). | G27: Chỉ CHU_NHA; tieuDe, noiDung không rỗng. | H27: phamVi = TOAN_TOA; gửi đến mọi tài khoản KHACH_THUE đang HOAT_DONG. | J27: UC08.01 | K27: Chủ nhà | L27: ERD v1.5
A28: 24 | B28: ThongBaoNguoiNhan | C28: danhDauDaDoc | E28: void | F28: Đánh dấu đã đọc. | G28: Chỉ chủ của tài khoản nhận. | H28: daDoc = true; thoiDiemDoc = now(). | J28: UC08.02 | K28: Chủ nhà, Khách thuê | L28: ERD v1.5
A29: 25 | B29: ThongBaoNguoiNhan | C29: demChuaDoc | D29: maTaiKhoan: String | E29: int | F29: Đếm số thông báo chưa đọc (số trên biểu tượng chuông). | H29: COUNT daDoc = false. | J29: UC08.02 | K29: Chủ nhà, Khách thuê | L29: ERD v1.5
A30: 26 | B30: KhachThue | C30: timTheoSDT | D30: sdt: String | E30: KhachThue | null | F30: Tìm hồ sơ cũ khi khách thuê lại. | H30: Trả hồ sơ nếu SĐT đã có. | I30: BR-CT-06 | J30: UC03.01 | K30: Chủ nhà | L30: ERD v1.5
A31: 27 | B31: KhachThue | C31: capNhatHoSo | D31: hoTen, ngaySinh, soCCCD, anhCCCD, queQuan, noiLamViec | E31: void | F31: Tạo / cập nhật hồ sơ khách. | G31: SĐT duy nhất; CCCD 12 số; ảnh CCCD lưu thư mục không công khai. | H31: Lưu hồ sơ; hồ sơ giữ lại sau khi trả phòng. | I31: BR-CT-06 | J31: UC03.01 | K31: Chủ nhà | L31: ERD v1.5
A32: 28 | B32: KhachThue | C32: layLichSuThue | E32: List<HopDong> | F32: Danh sách các HĐ khách đã đứng tên. | H32: Sắp xếp ngayBatDau giảm dần. | J32: UC03.01 | K32: Chủ nhà | L32: ERD v1.5
A33: 29 | B33: HopDong | C33: taoMoi | D33: maPhong, maKhach, ngayBatDau, ngayHetHan, giaThue, tienCoc, dsDichVu, mucPhatTraTruoc, anhHopDong | E33: HopDong | F33: Lưu hợp đồng giấy lên hệ thống. | G33: Phòng TRONG; phòng chưa có HĐ CHO_NHAN_PHONG/HIEU_LUC; kiemTraThoiHan() = true; số người hợp lệ. | H33: trangThai = CHO_NHAN_PHONG; tạo HopDongDichVu; gọi lapThongBaoKyHopDong(); ghi NhatKyThaoTac. | I33: BR-CT-02, BR-CT-03, BR-CT-04 | J33: UC03.03 | K33: Chủ nhà | L33: ERD v1.5
A34: 30 | B34: HopDong | C34: inMauHopDong | E34: File (.docx/.pdf) | F34: In mẫu hợp đồng điền sẵn để ký giấy. | G34: File mẫu cài sẵn khi bàn giao phần mềm (không lưu trong CSDL). | H34: File điền sẵn thông tin tòa, phòng, khách, giá thuê, cọc, thời hạn. | J34: UC03.04 | K34: Chủ nhà | L34: ERD v1.5
A35: 31 | B35: HopDong | C35: kiemTraThoiHan | E35: boolean | F35: Kiểm tra thời hạn tối thiểu 3 tháng. | H35: true khi ngayHetHan ≥ ngayBatDau + 3 tháng − 1 ngày; false → chặn lưu. | I35: BR-CT-02 | J35: UC03.03 | K35: Hệ thống | L35: ERD v1.5
A36: 32 | B36: HopDong | C36: lapThongBaoKyHopDong | E36: ThongBaoTien | F36: Lập thông báo tiền khi ký: cọc + tiền phòng từ ngày vào đến hết tháng. | G36: trangThai = CHO_NHAN_PHONG. | H36: ThongBaoTien loai KY_HOP_DONG gồm dòng TIEN_COC và TIEN_PHONG (tinhTienPhong(ngayBatDau, cuối tháng)); phát hành ngay. | J36: UC03.05 | K36: Hệ thống | L36: ERD v1.5
A37: 33 | B37: HopDong | C37: xacNhanNhanPhong | D37: lyDo: String, nguoiO?: NguoiO | E37: void | F37: Xác nhận bàn giao và nhận phòng. | G37: trangThai = CHO_NHAN_PHONG; có ChiSo DAU_KY điện (và nước nếu có công tơ); có BanGiaoTaiSan NHAN_PHONG; thông báo KY_HOP_DONG = DA_THU_DU, nếu chưa thì bắt buộc lyDo. | H37: trangThai = HIEU_LUC; lưu lyDoNhanPhongChuaThuDu (nếu có); ngayNhanPhong = hôm nay; Phong → DANG_THUE; gọi TaiKhoan.taoTaiKhoanKhach(this, nguoiO) – nguoiO là người được cấp tài khoản chủ nhà chọn trên CN-03.03; ghi NhatKyThaoTac. | I37: BR-CT-05, BR-DM-04 | J37: UC03.06 | K37: Chủ nhà | L37: ERD v1.5 · sửa ver1.4
A38: 34 | B38: HopDong | C38: themNguoiO | D38: nguoiO: NguoiO | E38: void | F38: Khai báo thêm người ở cùng. | G38: Phong.kiemTraSoNguoi(demSoNguoiO() + 1) = true. | H38: Thêm NguoiO; nếu HĐ đã hiệu lực ghi LichSuHopDong (THEM_NGUOI_O). | I38: BR-CT-04 | J38: UC03.02 | K38: Chủ nhà | L38: ERD v1.5
A39: 35 | B39: HopDong | C39: demSoNguoiO | E39: int | F39: Đếm số người đang ở. | H39: 1 (người đứng tên) + số NguoiO có ngayRa = null. | I39: BR-CT-04 | K39: Hệ thống | L39: ERD v1.5
A40: 36 | B40: HopDong | C40: giaHan | D40: ngayHetHanMoi: Date, giaMoi: decimal, anhPhuLuc | E40: void | F40: Gia hạn hợp đồng theo phụ lục giấy. | G40: trangThai = HIEU_LUC; chưa báo trả; ngayHetHanMoi ≥ ngayHetHan + 3 tháng; có ảnh phụ lục. | H40: Cập nhật ngayHetHan (và giaThue nếu đổi); ghi LichSuHopDong GIA_HAN (+ DIEU_CHINH_GIA) với ngayApDung = ngayHetHan cũ + 1. | I40: BR-CT-02 | J40: UC04.02 | K40: Chủ nhà | L40: ERD v1.5
A41: 37 | B41: HopDong | C41: dieuChinhGia | D41: giaMoi: decimal, ngayApDung: Date, anhPhuLuc | E41: void | F41: Điều chỉnh giá thuê trong thời hạn HĐ. | G41: trangThai = HIEU_LUC; ngayApDung là ngày 1 của tháng; giaMoi > 0. | H41: Cập nhật giaThue; ghi LichSuHopDong DIEU_CHINH_GIA. | J41: UC04.02 | K41: Chủ nhà | L41: ERD v1.5
...

Sheet 4_DanhMuc_Enum
A1: 4. DANH MỤC GIÁ TRỊ ENUM
A2: Code lưu CSDL dạng UPPER_SNAKE_CASE; nhãn hiển thị tiếng Việt trên giao diện. 'Suy luận' = tài liệu không liệt kê tường minh.
A4: STT | B4: Kiểu enum | C4: Giá trị (code) | D4: Nhãn hiển thị | E4: Ý nghĩa / ghi chú | F4: Dùng tại | G4: Căn cứ
A5: 1 | B5: VaiTro | C5: CHU_NHA | D5: Chủ nhà | E5: Quản trị hệ thống; đúng 1 tài khoản | F5: TaiKhoan.vaiTro, LichSuSuCo.vaiTroThucHien | G5: Mô tả YC – Người dùng
A6: 2 | B6: VaiTro | C6: KHACH_THUE | D6: Khách thuê | E6: 1 tài khoản / phòng
A7: 3 | B7: TrangThaiTK | C7: HOAT_DONG | D7: Hoạt động | F7: TaiKhoan.trangThai | G7: Suy luận từ mục 11
A8: 4 | B8: TrangThaiTK | C8: KHOA_TAM | D8: Khóa tạm | E8: Sau 5 lần nhập sai
A9: 5 | B9: TrangThaiTK | C9: DA_KHOA | D9: Đã khóa | E9: Khi thanh lý HĐ hoặc chủ nhà khóa
A10: 6 | B10: TrangThaiPhong | C10: TRONG | D10: Trống | F10: Phong.trangThai | G10: Sơ đồ trạng thái
A11: 7 | B11: TrangThaiPhong | C11: DANG_THUE | D11: Đang thuê | E11: Nhãn phụ 'Sắp trả' khi đã báo trả
A12: 8 | B12: TrangThaiPhong | C12: NGUNG_KHAI_THAC | D12: Ngừng khai thác
A13: 9 | B13: LoaiKhoan | C13: DIEN | D13: Điện | E13: (Chỉ số cuối − đầu) × đơn giá; đơn vị kWh | F13: BangGia.loaiKhoan | G13: Mô tả YC 2.2
A14: 10 | B14: LoaiKhoan | C14: NUOC | D14: Nước theo công tơ | E14: Đơn vị m3
A15: 11 | B15: LoaiKhoan | C15: NUOC_THEO_NGUOI | D15: Nước theo người | E15: Phòng không có công tơ nước riêng; đơn vị người/tháng
A16: 12 | B16: LoaiKhoan | C16: DICH_VU_THEO_PHONG | D16: Phí dịch vụ theo phòng | E16: Internet, vệ sinh…
A17: 13 | B17: LoaiKhoan | C17: DICH_VU_THEO_XE | D17: Phí dịch vụ theo xe | E17: Gửi xe; nhân số xe
A18: 14 | B18: TrangThaiHD | C18: CHO_NHAN_PHONG | D18: Chờ nhận phòng | E18: Đã lưu HĐ, chưa xác nhận nhận phòng | F18: HopDong.trangThai | G18: Sơ đồ trạng thái QT v1.3
A19: 15 | B19: TrangThaiHD | C19: HIEU_LUC | D19: Hiệu lực | E19: Gia hạn, điều chỉnh, báo trả vẫn giữ Hiệu lực
A20: 16 | B20: TrangThaiHD | C20: DA_THANH_LY | D20: Đã thanh lý
A21: 17 | B21: LoaiKetThuc | C21: KHACH_BAO_TRA | D21: Khách báo trả | F21: HopDong.loaiKetThuc | G21: Mô tả YC P05 – Trigger
A22: 18 | B22: LoaiKetThuc | C22: HET_HAN | D22: Hết hạn không gia hạn
A23: 19 | B23: LoaiKetThuc | C23: CHAM_DUT_VI_PHAM | D23: Chủ nhà chấm dứt do vi phạm
A24: 20 | B24: LoaiBanGiao | C24: NHAN_PHONG | D24: Nhận phòng | F24: BanGiaoTaiSan.loaiBanGiao | G24: Suy luận
A25: 21 | B25: LoaiBanGiao | C25: TRA_PHONG | D25: Trả phòng
A26: 22 | B26: LoaiThayDoi | C26: GIA_HAN | D26: Gia hạn | F26: LichSuHopDong.loaiThayDoi | G26: Mô tả YC P04
A27: 23 | B27: LoaiThayDoi | C27: DIEU_CHINH_GIA | D27: Điều chỉnh giá thuê
A28: 24 | B28: LoaiThayDoi | C28: DIEU_CHINH_PHI | D28: Điều chỉnh phí dịch vụ
A29: 25 | B29: LoaiThayDoi | C29: THEM_NGUOI_O | D29: Thêm người ở
A30: 26 | B30: LoaiThayDoi | C30: BOT_NGUOI_O | D30: Bớt người ở
A31: 27 | B31: LoaiCongTo | C31: DIEN | D31: Điện | F31: ChiSo.loaiCongTo | G31: Suy luận
A32: 28 | B32: LoaiCongTo | C32: NUOC | D32: Nước
A33: 29 | B33: LoaiGhi | C33: DAU_KY | D33: Đầu kỳ | E33: Khi nhận phòng hoặc khởi tạo dữ liệu | F33: ChiSo.loaiGhi | G33: Suy luận
A34: 30 | B34: LoaiGhi | C34: HANG_THANG | D34: Hằng tháng | E34: Ngày chốt chỉ số
A35: 31 | B35: LoaiGhi | C35: CUOI_KY | D35: Cuối kỳ | E35: Khi trả phòng
A36: 32 | B36: LoaiThongBao | C36: KY_HOP_DONG | D36: Thu khi ký HĐ | E36: Cọc + tiền phòng tháng đầu | F36: ThongBaoTien.loaiThongBao | G36: Suy luận
A37: 33 | B37: LoaiThongBao | C37: HANG_THANG | D37: Hằng tháng
A38: 34 | B38: LoaiThongBao | C38: THU_THEM_QUYET_TOAN | D38: Thu thêm sau quyết toán | E38: Số quyết toán âm
A39: 35 | B39: TrangThaiTBT | C39: NHAP | D39: Nháp | E39: Xóa được, không qua Đã hủy | F39: ThongBaoTien.trangThai | G39: Sơ đồ trạng thái QT v1.3
A40: 36 | B40: TrangThaiTBT | C40: DA_PHAT_HANH | D40: Đã phát hành | E40: Thuộc nhóm Chưa thu đủ
A41: 37 | B41: TrangThaiTBT | C41: CHO_XAC_NHAN | D41: Chờ xác nhận | E41: Khách báo đã chuyển khoản
...

Sheet 5_QuanHe
A1: 5. QUAN HỆ GIỮA CÁC THỰC THỂ (ERD v1.7 – gồm D30, D31 bổ sung ver1.4)
A2: Đọc: 1 [Lớp A] — [Bội số B] [Lớp B].
A4: Mã | B4: Lớp A | C4: Bội số A | D4: Lớp B | E4: Bội số B | F4: Tên quan hệ | G4: Mô tả | H4: Khóa ngoại thực hiện
A5: D1 | B5: ToaNha | C5: 1 | D5: Phong | E5: 1..n | F5: Có | G5: Tòa có nhiều phòng | H5: Phong.maToa
A6: D2 | B6: ToaNha | C6: 1 | D6: BangGia | E6: 1..n | F6: Áp dụng | G6: Tòa áp dụng bảng giá chung | H6: BangGia.maToa
A7: D3 | B7: Phong | C7: 1 | D7: TaiSan | E7: 0..n | F7: Trang bị | G7: Phòng có tài sản | H7: TaiSan.maPhong
A8: D4 | B8: Phong | C8: 1 | D8: SuCo | E8: 0..n | F8: Phát sinh | G8: Phòng phát sinh sự cố | H8: SuCo.maPhong
A9: D5 | B9: SuCo | C9: 1 | D9: LichSuSuCo | E9: 1..n | F9: Ghi lịch sử | G9: Sự cố có lịch sử xử lý | H9: LichSuSuCo.maSuCo
A10: D6 | B10: Phong | C10: 1 | D10: HopDong | E10: 0..n | F10: Được thuê | G10: Mỗi lúc tối đa 1 HĐ hiệu lực (BR-CT-03) | H10: HopDong.maPhong
A11: D7 | B11: TaiSan | C11: 1 | D11: BanGiaoTaiSan | E11: 0..n | F11: Được kiểm tra | G11: Tài sản được kiểm tra mỗi lần bàn giao | H11: BanGiaoTaiSan.maTaiSan
A12: D8 | B12: BangGia | C12: 1 | D12: HopDongDichVu | E12: 0..n | F12: Áp cho | G12: Khoản phí dịch vụ được áp cho HĐ | H12: HopDongDichVu.maKhoan
A13: D9 | B13: HopDong | C13: 1 | D13: HopDongDichVu | E13: 0..n | F13: Đăng ký | G13: HĐ áp dụng các phí dịch vụ | H13: HopDongDichVu.maHopDong
A14: D10 | B14: HopDong | C14: 1 | D14: BanGiaoTaiSan | E14: 0..n | F14: Bàn giao | G14: Bàn giao tài sản khi nhận / trả phòng | H14: BanGiaoTaiSan.maHopDong
A15: D11 | B15: KhachThue | C15: 1 | D15: HopDong | E15: 1..n | F15: Đứng tên | G15: Khách đứng tên HĐ (thuê lại → nhiều HĐ) | H15: HopDong.maKhach
... A35: D31 | B35: ThongBaoTien | C35: 0..1 | D35: DongThongBaoTien | E35: 0..n | F35: Điều chỉnh cho | G35: Dòng DIEU_CHINH tham chiếu thông báo đã thu bị sửa sai (BR-HD-04) | H35: DongThongBaoTien.maThongBaoTienGoc

Sheet 6_TrangThai
A1: 6. CHUYỂN TRẠNG THÁI
A2: Chuyển trạng thái không có trong bảng → phải bị chặn (ném lỗi nghiệp vụ).
A4: Đối tượng | B4: Từ trạng thái | C4: Đến trạng thái | D4: Phương thức / sự kiện | E4: Điều kiện | F4: Tác nhân | G4: Căn cứ
A5: Phong | B5: (tạo mới) | C5: TRONG | D5: Phong (tạo) | F5: Chủ nhà | G5: Sơ đồ trạng thái QT v1.3
A6: Phong | B6: TRONG | C6: DANG_THUE | D6: HopDong.xacNhanNhanPhong() | E6: Do hệ thống | F6: Hệ thống
A7: Phong | B7: DANG_THUE | C7: TRONG | D7: HopDong.thanhLy() | E7: Do hệ thống | F7: Hệ thống
A8: Phong | B8: TRONG | C8: NGUNG_KHAI_THAC | D8: Phong.chuyenTrangThai() | E8: Không có HĐ chưa thanh lý | F8: Chủ nhà
A9: Phong | B9: NGUNG_KHAI_THAC | C9: TRONG | D9: Phong.chuyenTrangThai() | F9: Chủ nhà
A10: Phong | B10: TRONG | C10: (đã xóa) | D10: Phong.xoa() | E10: Chưa từng có HĐ (BR-DM-03) | F10: Chủ nhà | G10: Bổ sung ver1.4
A11: HopDong | B11: (tạo mới) | C11: CHO_NHAN_PHONG | D11: HopDong.taoMoi() | E11: BR-CT-02, BR-CT-03, BR-CT-04 | F11: Chủ nhà | G11: Sơ đồ trạng thái QT v1.3
A12: HopDong | B12: CHO_NHAN_PHONG | C12: HIEU_LUC | D12: HopDong.xacNhanNhanPhong(lyDo) | E12: Đã thu đủ tiền ký HĐ hoặc có lý do (BR-CT-05) | F12: Chủ nhà
A13: HopDong | B13: HIEU_LUC | C13: HIEU_LUC | D13: giaHan() / dieuChinhGia() / baoTraPhong() | E13: Ghi LichSuHopDong; báo trả chỉ gắn nhãn Sắp trả | F13: Chủ nhà, Khách
A14: HopDong | B14: HIEU_LUC | C14: DA_THANH_LY | D14: HopDong.thanhLy() | E14: QuyetToan = HOAN_TAT | F14: Chủ nhà
A15: ThongBaoTien | B15: (tạo mới) | C15: NHAP | D15: lapThongBaoHangLoat() / lapThongBaoKyHopDong() | E15: Đủ chỉ số (BR-HD-02) | F15: Chủ nhà, Hệ thống | G15: Sơ đồ trạng thái QT v1.3
A16: ThongBaoTien | B16: NHAP | C16: DA_PHAT_HANH | D16: phatHanh() | F16: Chủ nhà
A17: ThongBaoTien | B17: DA_PHAT_HANH / DA_THU_MOT_PHAN | C17: QUA_HAN | D17: danhDauQuaHan() | E17: Ngày hiện tại > hanThanhToan | F17: Hệ thống
A18: ThongBaoTien | B18: Chưa thu đủ (DA_PHAT_HANH / QUA_HAN / DA_THU_MOT_PHAN) | C18: CHO_XAC_NHAN | D18: BaoThanhToan.guiBao() | E18: Khách báo đã chuyển khoản | F18: Khách
A19: ThongBaoTien | B19: CHO_XAC_NHAN | C19: Trạng thái trước khi báo | D19: BaoThanhToan.tuChoi(lyDo) | E19: Chưa thấy tiền | F19: Chủ nhà
A20: ThongBaoTien | B20: CHO_XAC_NHAN | C20: DA_THU_DU / DA_THU_MOT_PHAN | D20: BaoThanhToan.xacNhan() → capNhatTrangThaiThu() | E20: đủ: soDaThu ≥ tongTien; thiếu: 0 < soDaThu < tongTien | F20: Chủ nhà
A21: ThongBaoTien | B21: Chưa thu đủ (DA_PHAT_HANH / QUA_HAN / DA_THU_MOT_PHAN) | C21: DA_THU_DU / DA_THU_MOT_PHAN | D21: ghiNhanThu() → capNhatTrangThaiThu() | E21: Chủ nhà ghi nhận thu trực tiếp (tiền mặt hoặc chuyển khoản không qua báo CK) | F21: Chủ nhà
A22: ThongBaoTien | B22: DA_PHAT_HANH / QUA_HAN | C22: DA_HUY | D22: huy(lyDo) | E22: soDaThu = 0 (BR-HD-04) | F22: Chủ nhà
A23: BaoThanhToan | B23: (tạo mới) | C23: CHO_XAC_NHAN | D23: guiBao() | F23: Khách | G23: Ghi chú State Diagram v1.3
A24: BaoThanhToan | B24: CHO_XAC_NHAN | C24: DA_XAC_NHAN | D24: xacNhan() | F24: Chủ nhà
A25: BaoThanhToan | B25: CHO_XAC_NHAN | C25: TU_CHOI | D25: tuChoi(lyDo) | E25: Có lý do | F25: Chủ nhà
A26: PhieuThu | B26: (tạo mới) | C26: HIEU_LUC | D26: xacNhan() / ghiNhanThu() | F26: Chủ nhà | G26: Ghi chú State Diagram v1.3
A27: PhieuThu | B27: HIEU_LUC | C27: DA_HUY | D27: huy(lyDo) | E27: Có lý do (BR-TT-02) | F27: Chủ nhà
A28: SuCo | B28: (tạo mới) | C28: MOI | D28: baoSuCo() | F28: Khách | G28: Sơ đồ trạng thái QT v1.3
A29: SuCo | B29: MOI | C29: DANG_XU_LY | D29: tiepNhan(lichHen) | F29: Chủ nhà
A30: SuCo | B30: MOI | C30: TU_CHOI | D30: tuChoi(lyDo) | E30: Có lý do (BR-SC-02) | F30: Chủ nhà
A31: SuCo | B31: DANG_XU_LY | C31: DA_XU_LY | D31: hoanThanh() | F31: Chủ nhà
A32: SuCo | B32: DA_XU_LY | C32: MO_LAI | D32: moLai() | E32: Chưa khắc phục; không phản hồi thì giữ DA_XU_LY | F32: Khách
A33: SuCo | B33: MO_LAI | C33: DANG_XU_LY | D33: tiepNhan(lichHen) | F33: Chủ nhà
A34: QuyetToan | B34: (tạo mới) | C34: NHAP | D34: tinhQuyetToan() | F34: Hệ thống | G34: Sơ đồ trạng thái QT v1.3
A35: QuyetToan | B35: NHAP | C35: CHO_PHAN_HOI | D35: guiKhach() | E35: Chủ nhà đã rà soát | F35: Chủ nhà
A36: QuyetToan | B36: CHO_PHAN_HOI | C36: DA_CHOT | D36: khachPhanHoi(true) / chotQuyetToan(lyDo) | E36: Khách đồng ý, hoặc không phản hồi → chủ nhà chốt kèm lý do | F36: Khách, Chủ nhà
A37: QuyetToan | B37: CHO_PHAN_HOI | C37: KHACH_KHONG_DONG_Y | D37: khachPhanHoi(false, yKien) | E37: Có ý kiến của khách | F37: Khách
A38: QuyetToan | B38: KHACH_KHONG_DONG_Y | C38: CHO_PHAN_HOI | D38: themKhoanTru() → guiKhach() | E38: Điều chỉnh, ghi lý do (BR-TL-03) | F38: Chủ nhà
A39: QuyetToan | B39: KHACH_KHONG_DONG_Y | C39: DA_CHOT | D39: chotQuyetToan(lyDo) | E39: Có lý do (BR-TL-03) | F39: Chủ nhà
A40: QuyetToan | B40: DA_CHOT | C40: HOAN_TAT | D40: lapPhieuChi() / lapThongBaoThuThem() | F40: Chủ nhà
A41: TaiKhoan | B41: (tạo mới) | C41: HOAT_DONG | D41: taoTaiKhoanKhach() | E41: phaiDoiMatKhau = true | F41: Hệ thống | G41: Ghi chú State Diagram v1.3
...

Sheet 7_QuyTacNV
A1: 7. QUY TẮC NGHIỆP VỤ
A4: Mã | B4: Nội dung (nguyên văn Mô tả YC) | C4: Áp dụng tại lớp / phương thức
A5: BR-DM-01 | B5: Đổi đơn giá điện, nước áp dụng cho các thông báo lập sau thời điểm đổi; thông báo đã phát hành không bị tính lại. | C5: BangGia.doiDonGia, BangGia.layDonGiaTai
A6: BR-DM-02 | B6: Đổi giá niêm yết của phòng không làm thay đổi giá trên hợp đồng đang hiệu lực. | C6: Phong.capNhatGiaNiemYet
A7: BR-DM-03 | B7: Không xóa phòng đã có hợp đồng; chỉ chuyển sang Ngừng khai thác. | C7: Phong.coTheXoa, Phong.xoa
A8: BR-DM-04 | B8: Trạng thái Trống ↔ Đang thuê do hệ thống tự cập nhật khi nhận phòng và thanh lý; chủ nhà chỉ tự chuyển giữa Trống và Ngừng khai thác. | C8: Phong.chuyenTrangThai
A9: BR-CT-01 | B9: SĐT là tên đăng nhập của khách, duy nhất trong hệ thống; mỗi phòng có một tài khoản khách. | C9: TaiKhoan.tenDangNhap, TaiKhoan.taoTaiKhoanKhach, HopDong.maNguoiOCapTK
A10: BR-CT-02 | B10: Thời hạn hợp đồng tối thiểu 3 tháng; hệ thống chặn lưu hợp đồng ngắn hơn. | C10: HopDong.kiemTraThoiHan, HopDong.giaHan
A11: BR-CT-03 | B11: Mỗi phòng chỉ có một hợp đồng hiệu lực tại một thời điểm. | C11: HopDong.taoMoi, Phong.layHopDongHieuLuc
A12: BR-CT-04 | B12: Tổng số người ở (người đứng tên và người ở cùng) không vượt số người tối đa của phòng. | C12: Phong.kiemTraSoNguoi, HopDong.themNguoiO
A13: BR-CT-05 | B13: Không xác nhận nhận phòng khi thông báo tiền ký hợp đồng chưa thu đủ, trừ khi chủ nhà ghi lý do. | C13: HopDong.xacNhanNhanPhong
A14: BR-CT-06 | B14: Ảnh CCCD chỉ chủ nhà xem; khách chỉ xem hồ sơ của phòng mình. Hồ sơ khách giữ lại sau khi trả phòng để nhận diện khách thuê lại. | C14: KhachThue, phân quyền
A15: BR-HD-01 | B15: Mỗi phòng mỗi tháng một thông báo tiền chính; phí phát sinh giữa tháng cộng vào thông báo cuối tháng. | C15: DichVuThongBaoTien.lapThongBaoHangLoat
... A31: Mục 11 | B31: Đăng nhập SĐT + mật khẩu băm; khóa tạm sau 5 lần sai; mọi truy vấn của khách lọc theo phòng đang thuê ở tầng dữ liệu; ảnh CCCD ở thư mục không công khai; nhật ký thao tác cho HĐ, thông báo tiền, phiếu thu, chỉ số, xuất tạm trú; chủ nhà tra cứu nhật ký (UC01.09), nhật ký chỉ thêm, không sửa, xóa; sao lưu CSDL hằng ngày. | C31: TaiKhoan, NhatKyThaoTac, tầng truy cập dữ liệu

Sheet 8_PhanQuyen
A1: 8. PHÂN QUYỀN THEO VAI TRÒ
A2: Bộ hẹn giờ hệ thống chạy với quyền hệ thống (không đăng nhập).
A4: Dữ liệu, chức năng | B4: Chủ nhà | C4: Khách thuê
A5: Tòa, phòng, bảng giá | B5: Toàn quyền | C5: Xem nội quy tòa, phòng mình, bảng giá áp dụng và thông tin liên hệ chủ nhà
A6: Hồ sơ khách, CCCD | B6: Toàn quyền | C6: Xem hồ sơ phòng mình (không xem ảnh CCCD)
A7: Hợp đồng | B7: Toàn quyền | C7: Xem hợp đồng của mình
A8: Thông báo tiền, phiếu thu | B8: Lập, phát hành, xác nhận đã thu, ghi nhận thu trực tiếp (tiền mặt / chuyển khoản không qua báo CK), từ chối báo chuyển khoản, hủy thông báo tiền, hủy phiếu thu | C8: Xem, tải phiếu thu, báo đã chuyển khoản; nhận thông báo khi bị từ chối
A9: Sự cố | B9: Tiếp nhận, xử lý, từ chối | C9: Tạo, theo dõi, mở lại
A10: Báo trả, quyết toán | B10: Xử lý, lập quyết toán (thêm / sửa / xóa khoản trừ), xem / in phiếu chi | C10: Báo trả, xem và phản hồi quyết toán
A11: Thông báo chung, báo cáo, xuất tạm trú | B11: Toàn quyền | C11: Xem thông báo
A12: Tài khoản | B12: Tạo (khi nhận phòng, khi khởi tạo dữ liệu, cho HĐ hiệu lực chưa có tài khoản; chọn người được cấp), khóa, đặt lại mật khẩu khách | C12: Đổi mật khẩu của mình
A13: Nhật ký thao tác | B13: Tra cứu (chỉ xem) | C13: Không có quyền

Sheet 9_ViDu_TestCase
A1: 9. VÍ DỤ TÍNH TIỀN – DÙNG LÀM TEST CASE
A2: Nguồn: Mô tả YC mục 4 (P02) và mục 7 (P05). Ô chữ xanh = đầu vào; cột 'Kỳ vọng' là số in trong tài liệu.
A4: ĐẦU VÀO
A5: Giá thuê (VNĐ/tháng) | B5: 3000000
A6: Internet (VNĐ/tháng) | B6: 100000
A7: Tiền cọc (VNĐ) | B7: 3000000
A8: Ngày bắt đầu HĐ | B8: 46311
A9: Ngày hết hạn HĐ | B9: 46492
A12: Trường hợp | B12: Từ ngày | C12: Đến ngày | D12: Số ngày ở | E12: Số ngày của tháng | F12: Tỷ lệ ngày ở | G12: Đơn giá | H12: Thành tiền (công thức) | I12: Kỳ vọng theo tài liệu | J12: Khớp?
A13: Tiền phòng khi ký HĐ (16–31/10/2026) | B13: 46311 | C13: 46326 | D13: =C13-B13+1 -> 16 | E13: =DAY(DATE(YEAR(B13),MONTH(B13)+1,0)) -> 31 | F13: =D13/E13 -> 0.51612903 | G13: =$B$5 -> 3000000 | H13: =G13*F13 -> 1548387.1 | I13: 1548387 | J13: =IF(ROUND(H13,0)=I13,"OK","LỆCH") -> OK
A14: Internet tháng 10/2026 | B14: 46311 | C14: 46326 | D14: =C14-B14+1 -> 16 | E14: =DAY(DATE(YEAR(B14),MONTH(B14)+1,0)) -> 31 | F14: =D14/E14 -> 0.51612903 | G14: =$B$6 -> 100000 | H14: =G14*F14 -> 51612.903 | I14: 51613 | J14: =IF(ROUND(H14,0)=I14,"OK","LỆCH") -> OK
A15: Tiền phòng 1–15/04/2027 (chưa gia hạn) | B15: 46478 | C15: 46492 | D15: =C15-B15+1 -> 15 | E15: =DAY(DATE(YEAR(B15),MONTH(B15)+1,0)) -> 30 | F15: =D15/E15 -> 0.5 | G15: =$B$5 -> 3000000 | H15: =G15*F15 -> 1500000 | I15: 1500000 | J15: =IF(ROUND(H15,0)=I15,"OK","LỆCH") -> OK
A16: Internet tháng 4/2027 đến ngày trả | B16: 46478 | C16: 46492 | D16: =C16-B16+1 -> 15 | E16: =DAY(DATE(YEAR(B16),MONTH(B16)+1,0)) -> 30 | F16: =D16/E16 -> 0.5 | G16: =$B$6 -> 100000 | H16: =G16*F16 -> 50000 | I16: 50000 | J16: =IF(ROUND(H16,0)=I16,"OK","LỆCH") -> OK
A17: Tiền phòng tháng đủ (vd 11/2026) | B17: 46327 | C17: 46356 | D17: =C17-B17+1 -> 30 | E17: =DAY(DATE(YEAR(B17),MONTH(B17)+1,0)) -> 30 | F17: =D17/E17 -> 1 | G17: =$B$5 -> 3000000 | H17: =G17*F17 -> 3000000 | I17: 3000000 | J17: =IF(ROUND(H17,0)=I17,"OK","LỆCH") -> OK
A19: Thông báo khi ký HĐ (cọc + tiền phòng tháng đầu)
A20: Tổng chưa làm tròn | B20: =B7+H13 -> 4548387.1
A21: Tổng làm tròn 1.000 đ (BR-HD-05, giả định half-up) | B21: =ROUND(B20,-3) -> 4548000
A22: Ghi chú: ROUND(…, -3) trong Excel là làm tròn half-up đến hàng nghìn. Nếu chủ nhà muốn làm tròn xuống, đổi thành ROUNDDOWN và cập nhật ThongBaoTien.tinhTong().
A24: CÔNG THỨC NGHIỆP VỤ
A25: • Thông báo cuối tháng T: Tổng = điện, nước tháng T + phí dịch vụ tháng T + tiền phòng tháng T+1 + phí phát sinh + nợ cũ − giảm trừ (làm tròn tổng đến 1.000 đ).
A26: • Điện = (chỉ số cuối − chỉ số đầu) × đơn giá điện, không bậc thang. Nước = (chỉ số cuối − chỉ số đầu) × đơn giá nước; không có công tơ riêng → số người × đơn giá/người/tháng × tỷ lệ ngày ở.
A27: • Tỷ lệ ngày ở = số ngày ở / số ngày của tháng dương lịch; tính ngày nhận phòng, không tính ngày trả phòng.
A28: • Quyết toán: Số hoàn = cọc + tiền phòng đã thu cho các ngày chưa ở − điện, nước, phí dịch vụ đến ngày trả − nợ chưa trả − bồi thường hư hỏng − phạt trả trước hạn (nếu có). >0 → phiếu chi; <0 → thông báo thu thêm.
A29: • Ví dụ trả phòng 16/04/2027 đúng hạn: số hoàn = 3.000.000 − điện, nước 1–15/04 − 50.000 đ internet − bồi thường (nếu có); không có hoàn tiền phòng.

Sheet 10_ThayDoi_ver1.4
A1: STT | B1: Sheet | C1: Đối tượng | D1: Thay đổi | E1: Căn cứ (Sidebar v1.3)
A2: 1 | B2: 3 | C2: ThongBaoTien.thuTienMat → ghiNhanThu | D2: Đổi tên, thêm tham số hinhThuc, ngayThu; cho phép ghi nhận chuyển khoản không qua báo CK; chặn khi đang CHO_XAC_NHAN | E2: CN-05.03, CN-03.03 · TT.THU_TRUC_TIEP
A3: 2 | B3: 2, 3, 5 | C3: HopDong.maNguoiOCapTK · TaiKhoan.taoTaiKhoanKhach · HopDong.xacNhanNhanPhong | D3: Thuộc tính mới (FK NguoiO, quan hệ D30); tham số người được cấp tài khoản; NguoiO.soDienThoai bắt buộc khi được cấp | E3: CN-03.03 · TK_KHACH.TAO
A4: 3 | B4: 3 | C4: DichVuKhoiTao.nhapDuLieuDangVanHanh | D4: Thêm dsNguoiO, dsDichVu; tạo tài khoản khách cho từng HĐ, trả danh sách mật khẩu tạm | E4: CN-09.04, CN-09.03
A5: 4 | B5: 3, 6, 7 | C5: Phong.xoa (mới) | D5: Xóa phòng chưa từng có HĐ; thêm dòng chuyển trạng thái; BR-DM-03 | E5: CN-02.01 · PHONG.XOA
A6: 5 | B6: 2, 3, 5, 7 | C6: DongThongBaoTien.maThongBaoTienGoc · ThongBaoTien.themDong | D6: Dòng DIEU_CHINH phải tham chiếu thông báo đã thu (quan hệ D31); BR-HD-04 | E6: CN-05.02 · TBT.PHI_PHAT_SINH
A7: 6 | B7: 3, 7 | C7: QuyetToan.suaKhoanTru, xoaKhoanTru (mới) | D7: Sửa / xóa khoản trừ khi Nháp hoặc khách không đồng ý, ghi lý do | E7: CN-04.02 · QT.LAP
A8: 7 | B8: 3 | C8: QuyetToan.lapPhieuChi | D8: Ghi nhật ký; xem / in phiếu chi | E8: CN-04.02 · QT.PHIEU_CHI
A9: 8 | B9: 2, 3 | C9: HopDong.daThuHoiChiaKhoa · xacNhanThuHoiChiaKhoa (mới) · thanhLy | D9: Xác nhận thu hồi chìa khóa khi kiểm tra phòng; thanh lý cảnh báo nếu chưa thu hồi | E9: CN-04.01 · TRA.KIEM_TRA
A10: 9 | B10: 3 | C10: ToaNha.capNhatTaiKhoanNhanTien | D10: Thêm tham số diaChiChuNha; tên, SĐT chủ nhà hiện cho khách | E10: CN-09.02, KT-01.01
A11: 10 | B11: 3 | C11: DichVuViecCanLam.layDanhSach | D11: Thêm "yêu cầu trả phòng mới" cho khớp CN-01.01 | E11: CN-01.01
A12: 11 | B12: 3 | C12: ThongBaoTien.phatHanh | D12: Tác nhân Chủ nhà, Hệ thống (gọi từ phát hành hàng loạt / tự phát hành thông báo ký HĐ, thu thêm) | E12: CN-05.02 · TBT.PHAT_HANH
A13: 12 | B13: 2 | C13: NhatKyThaoTac.doiTuong | D13: Thêm Phong, PhieuChi vào miền giá trị | E13: PHONG.XOA, QT.PHIEU_CHI
... A16: 15 | B16: 5 | C16: Tiêu đề quan hệ | D16: Đồng bộ với ERD_ChungCuMini_ver1.7 (3 thuộc tính, 4 phương thức, 2 quan hệ mới đã vẽ trên ERD) | E16: —
